<mujoco model="panda">
    <compiler angle="radian" autolimits="true"/>
    <option integrator="implicitfast"/>
    <size njmax="500" nconmax="100" />
    <asset>
        <mesh name="link0" file="link0.stl" />
        <mesh name="link1" file="link1.stl" />
        <mesh name="link2" file="link2.stl" />
        <mesh name="link3" file="link3.stl" />
        <mesh name="link4" file="link4.stl" />
        <mesh name="link5" file="link5.stl" />
        <mesh name="link6" file="link6.stl" />
        <mesh name="link7" file="link7.stl" />
        <mesh name="hand" file="hand.stl" />
        <mesh name="finger" file="finger.stl" />
    </asset>
    <worldbody>
        <geom type="mesh" rgba="1 1 1 1" mesh="link0" />
        <body name="panda_link1" pos="0 0 0.333">
            <inertial pos="0 -0.04 -0.05" mass="2.7" diaginertia="0.1 0.1 0.1" />
            <joint name="panda_joint1" pos="0 0 0" axis="0 0 1" limited="true" range="-2.8973 2.8973" />
            <body name="panda_link2" pos="0 0 0" quat="0.707107 -0.707107 0 0">
                <inertial pos="0 -0.04 0.06" mass="2.73" diaginertia="0.1 0.1 0.1" />
                <joint name="panda_joint2" pos="0 0 0" axis="0 0 1" limited="true" range="-1.7628 1.7628" />
                <body name="panda_link3" pos="0 -0.316 0" quat="0.707107 0.707107 0 0">
                    <inertial pos="0.01 0.01 -0.05" mass="2.04" diaginertia="0.1 0.1 0.1" />
                    <joint name="panda_joint3" pos="0 0 0" axis="0 0 1" limited="true" range="-2.8973 2.8973" />
                    <body name="panda_link4" pos="0.0825 0 0" quat="0.707107 0.707107 0 0">
                        <inertial pos="-0.03 0.03 0.02" mass="2.08" diaginertia="0.1 0.1 0.1" />
                        <joint name="panda_joint4" pos="0 0 0" axis="0 0 1" limited="true" range="-3.0718 -0.0698" />
                        <body name="panda_link5" pos="-0.0825 0.384 0" quat="0.707107 -0.707107 0 0">
                            <inertial pos="0 0.04 -0.12" mass="3" diaginertia="0.1 0.1 0.1" />
                            <joint name="panda_joint5" pos="0 0 0" axis="0 0 1" limited="true" range="-2.8975 2.8975" />
                            <body name="panda_link6" pos="0 0 0" quat="0.707107 0.707107 0 0">
                                <inertial pos="0.04 0 0" mass="1.3" diaginertia="0.1 0.1 0.1" />
                                <joint name="panda_joint6" pos="0 0 0" axis="0 0 1" limited="true" range="-0.0175 3.7525" />
                                <body name="panda_link7" pos="0.088 0 0" quat="0.707107 0.707107 0 0">
                                    <inertial pos="0 0 0.139216" mass="1.02" diaginertia="0.201001 0.201001 0.2001" />
                                    <joint name="panda_joint7" pos="0 0 0" axis="0 0 1" limited="true" range="-2.8973 2.8973" />
                                    <geom pos="0 0 0.113" quat="0.92388 0 0 -0.382683" type="mesh" rgba="1 1 1 1" mesh="hand" />
                                    <body name="panda_leftfinger" pos="0.0282843 0.0282843 0.2394" quat="0.65328 0.2706 -0.653282 0.270599">
                                        <inertial pos="0 0.01 0.02" mass="0.1" diaginertia="0.1 0.1 0.1" />
                                        <joint name="panda_finger_joint1" pos="0 0 0" axis="0 0 1" type="slide" limited="true" range="0 0.04" />
                                        <geom type="mesh" rgba="1 1 1 1" mesh="finger" />
                                    </body>
                                    <body name="panda_rightfinger" pos="-0.0282843 -0.0282843 0.2394" quat="0.65328 -0.2706 0.653282 0.270599">
                                        <inertial pos="0 -0.01 0.02" mass="0.1" diaginertia="0.1 0.1 0.1" />
                                        <joint name="panda_finger_joint2" pos="0 0 0" axis="0 0 1" type="slide" limited="true" range="0 0.04" />
                                        <geom quat="0 0 0 1" type="mesh" rgba="1 1 1 1" mesh="finger" />
                                    </body>
                                </body>
                            </body>
                        </body>
                    </body>
                </body>
            </body>
        </body>
    </worldbody>
    <actuator>
        <general name="actuator1" joint="panda_joint1" gainprm="10000" biasprm="0 -10000 -1000"/>
        <general name="actuator2" joint="panda_joint2" gainprm="10000" biasprm="0 -10000 -1000" ctrlrange="-1.7628 1.7628"/>
        <general name="actuator3" joint="panda_joint3" gainprm="10000" biasprm="0 -10000 -1000"/>
        <general name="actuator4" joint="panda_joint4" gainprm="10000" biasprm="0 -10000 -1000" ctrlrange="-3.0718 -0.0698"/>
        <general name="actuator5" joint="panda_joint5" gainprm="10000" biasprm="0 -10000 -1000"/>
        <general name="actuator6" joint="panda_joint6" gainprm="10000" biasprm="0 -10000 -1000" ctrlrange="-0.0175 3.7525"/>
        <general name="actuator7" joint="panda_joint7" gainprm="10000" biasprm="0 -10000 -1000"/>
        <general name="finger_actuator1" joint="panda_finger_joint1" forcerange="-100 100" ctrlrange="0 0.04" gainprm="100 0 0" biasprm="0 -100 -10"/>
        <general name="finger_actuator2" joint="panda_finger_joint2" forcerange="-100 100" ctrlrange="0 0.04" gainprm="100 0 0" biasprm="0 -100 -10"/>

    </actuator>
</mujoco>
