<?xml version="1.0" encoding="UTF-8"?>
<!--This file is auto-generated from the robot URDF file: meta.urdf.
Source file has been updated on <please fill the date if changed>.
This file has been manually updated on <03/12/2019>.
-->
<robot name="meta">
  <material name="white_material">
    <color rgba="1.0 1.0 1.0 1.0"/>
    <specular value="1.0"/>
  </material>
  <link name="link_base">
    <contact>
      <stiffness value="1e5"/>
      <damping value="1e3"/>
      <lateral_friction value="0.1"/>
      <rolling_friction value="0.0"/>
    </contact>
    <inertial>
      <mass value="52.9101052160097"/>
      <origin xyz="-0.142542994624505 2.33339305547787E-03 0.130110970092973" rpy="0.0 0.0 0.0"/>
      <inertia ixx="2.78321475990223" ixy="1.02013636219535E-03" ixz="-0.544719331016329" iyy="3.24941132525702" iyz="7.51942241521894E-03" izz="1.33602142044359"/>
    </inertial>
    <visual>
      <origin xyz="0.0 0.0 0.0" rpy="0 0 0"/>
      <geometry>
        <mesh filename="3obj/link_base.glb"/>
      </geometry>
    </visual>

    <collision>
      <origin xyz="0.0 0.0 0.0" rpy="0 0 0"/>
      <geometry>
        <mesh filename="coarse_meshes/link_base_0.glb"/>
      </geometry>
    </collision>
    <collision>
      <origin xyz="0.0 0.0 0.0" rpy="0 0 0"/>
      <geometry>
        <mesh filename="coarse_meshes/link_base_1.glb"/>
      </geometry>
    </collision>
    <collision>
      <origin xyz="0.0 0.0 0.0" rpy="0 0 0"/>
      <geometry>
        <mesh filename="coarse_meshes/link_base_2.glb"/>
      </geometry>
    </collision>
    <collision>
      <origin xyz="0.0 0.0 0.0" rpy="0 0 0"/>
      <geometry>
        <mesh filename="coarse_meshes/link_base_3.glb"/>
      </geometry>
    </collision>
    <collision>
      <origin xyz="0.0 0.0 0.0" rpy="0 0 0"/>
      <geometry>
        <mesh filename="coarse_meshes/link_base_4.glb"/>
      </geometry>
    </collision>
    <collision>
      <origin xyz="0.0 0.0 0.0" rpy="0 0 0"/>
      <geometry>
        <mesh filename="coarse_meshes/link_base_5.glb"/>
      </geometry>
    </collision>
  </link>

  <link name="link_torso">
    <inertial>
      <mass value="1.8957478141399"/>
      <origin xyz="-3.49440775620019E-03 -6.07148425485309E-02 0.111756043503709" rpy="0.0 0.0 0.0"/>
      <inertia ixx="1.33075265762797E-02" ixy="1.89697020107391E-04" ixz="2.61969764388555E-05" iyy="6.70473236899565E-03" iyz="1.74650164172695E-04" izz="0.01146044402243"/>
    </inertial>
    <visual>
      <origin xyz="0.0 0.0 0.0" rpy="0 0 0"/>
      <geometry>
        <mesh filename="3obj/link_torso.3obj.obj"/>
      </geometry>
    </visual>
    <collision>
      <origin xyz="0.0 0.0 0.0" rpy="0 0 0"/>
      <geometry>
        <mesh filename="coarse_meshes/link_torso_vhacd.obj"/>
      </geometry>
    </collision>
  </link>
  <link name="link_shoulder">
    <inertial>
      <mass value="1.84719381890442"/>
      <origin xyz="1.08073648299081E-03 4.80943923806668E-03 0.104943810827839" rpy="0.0 0.0 0.0"/>
      <inertia ixx="1.39748177932869E-02" ixy="-4.34243299680672E-05" ixz="-1.63555207176536E-05" iyy="1.42491663186364E-02" iyz="4.46239649689696E-04" izz="2.94679102626988E-03"/>
    </inertial>
    <visual>
      <origin xyz="0.0 0.0 0.0" rpy="0 0 0"/>
      <geometry>
        <mesh filename="3obj/link_shoulder.3obj.obj"/>
      </geometry>
    </visual>
    <collision>
      <origin xyz="0.0 0.0 0.0" rpy="0 0 0"/>
      <geometry>
        <mesh filename="coarse_meshes/link_shoulder_vhacd.obj"/>
      </geometry>
    </collision>
  </link>
  <link name="link_bicep">
    <inertial>
      <mass value="1.24742039827471"/>
      <origin xyz="4.09029241155202E-04 -2.11440998419464E-02 0.135242657168686" rpy="0.0 0.0 0.0"/>
      <inertia ixx="7.04679718538362E-03" ixy="1.36969628307193E-10" ixz="3.84597629359556E-05" iyy="6.88742202474402E-03" iyz="9.28918679930493E-04" izz="1.85445900824595E-03"/>
    </inertial>
    <visual>
      <origin xyz="0.0 0.0 0.0" rpy="0 0 0"/>
      <geometry>
        <mesh filename="3obj/link_bicep.3obj.obj"/>
      </geometry>
    </visual>
    <collision>
      <origin xyz="0.0 0.0 0.0" rpy="0 0 0"/>
      <geometry>
        <mesh filename="coarse_meshes/link_bicep_vhacd.obj"/>
      </geometry>
    </collision>
  </link>
  <link name="link_elbow">
    <inertial>
      <mass value="0.646384675806209"/>
      <origin xyz="1.73027427722836E-03 -7.65653785661243E-02 3.67058126361657E-02" rpy="0.0 0.0 0.0"/>
      <inertia ixx="1.78669367379914E-03" ixy="4.72737764012305E-09" ixz="1.63948789791547E-05" iyy="1.18491737676627E-03" iyz="4.57024538361969E-04" izz="1.3174964153246E-03"/>
    </inertial>
    <visual>
      <origin xyz="0.0 0.0 0.0" rpy="0 0 0"/>
      <geometry>
        <mesh filename="3obj/link_elbow.3obj.obj"/>
      </geometry>
    </visual>
    <collision>
      <origin xyz="0.0 0.0 0.0" rpy="0 0 0"/>
      <geometry>
        <mesh filename="coarse_meshes/link_elbow_vhacd.obj"/>
      </geometry>
    </collision>
  </link>
  <link name="link_forearm">
    <inertial>
      <mass value="0.724366583650768"/>
      <origin xyz="1.27504320016631E-05 0.015087509138929 0.181814236861875" rpy="0.0 0.0 0.0"/>
      <inertia ixx="7.2105415923413E-03" ixy="1.04502358823027E-07" ixz="1.31044797457377E-06" iyy="7.15752801157893E-03" iyz="-5.11256783255503E-04" izz="5.91583070198947E-04"/>
    </inertial>
    <visual>
      <origin xyz="0.0 0.0 0.0" rpy="0 0 0"/>
      <geometry>
        <mesh filename="3obj/link_forearm.3obj.obj"/>
      </geometry>
    </visual>
    <collision>
      <origin xyz="0.0 0.0 0.0" rpy="0 0 0"/>
      <geometry>
        <mesh filename="coarse_meshes/link_forearm_vhacd.obj"/>
      </geometry>
    </collision>
  </link>
  <link name="link_wrist">
    <inertial>
      <mass value="0.501929332223751"/>
      <origin xyz="-2.97206845574571E-04 -7.32716069306932E-03 5.36615347785701E-02" rpy="0.0 0.0 0.0"/>
      <inertia ixx="1.14262626699036E-03" ixy="-2.30402238037496E-06" ixz="-6.14792965371237E-06" iyy="1.07002285178686E-03" iyz="-2.60092608214865E-04" izz="4.2713626545483E-04"/>
    </inertial>
    <visual>
      <origin xyz="0.0 0.0 0.0" rpy="0 0 0"/>
      <geometry>
        <mesh filename="3obj/link_wrist.3obj.obj"/>
      </geometry>
    </visual>
    <collision>
      <origin xyz="0.0 0.0 0.0" rpy="0 0 0"/>
      <geometry>
        <mesh filename="coarse_meshes/link_wrist_vhacd.obj"/>
      </geometry>
    </collision>
  </link>
  <link name="link_gripper">
    <inertial>
      <mass value="0.40507013"/>
      <origin xyz="4.2266E-04 1.1761E-04 0.03790068" rpy="0.0 0.0 0.0"/>
      <inertia ixx="2.9237E-04" ixy="3.59E-06" ixz="2.66E-06" iyy="2.6364E-04" iyz="6.6E-07" izz="3.1135E-04"/>
    </inertial>
    <visual>
      <origin xyz="0.0 0.0 0.0" rpy="0 0 -1.57079632679"/>
      <geometry>
        <mesh filename="3obj/link_gripper.3obj.obj"/>
      </geometry>
    </visual>
    <collision>
      <origin xyz="0.0 0.0 0.0" rpy="0 0 -1.57079632679"/>
      <geometry>
        <mesh filename="coarse_meshes/link_gripper_vhacd.obj"/>
      </geometry>
    </collision>
  </link>

  <link name="link_head_pan">
    <inertial>
      <mass value="0.96335794"/>
      <origin xyz="1.64010030935057E-02 -5.7398337011911E-04 8.68775033608304E-02" rpy="0.0 0.0 0.0"/>
      <inertia ixx="1.99658E-03" ixy="-2.2593E-04" ixz="5.3396E-04" iyy="2.82709E-03" iyz="-1.2776E-04" izz="2.40811E-03"/>
    </inertial>
    <visual>
      <origin xyz="0.0 0.0 0.0" rpy="0 0 0"/>
      <geometry>
        <mesh filename="3obj/link_head_pan.3obj.obj"/>
      </geometry>
    </visual>
    <collision>
      <origin xyz="0.0 0.0 0.0" rpy="0 0 0"/>
      <geometry>
        <mesh filename="coarse_meshes/link_head_pan_vhacd.obj"/>
      </geometry>
    </collision>
  </link>
  <link name="link_head_tilt">
    <inertial>
      <mass value="0.879240552641472"/>
      <origin xyz="7.28448960084497E-02 -3.00449029242004E-03 1.32833990979786E-03" rpy="0.0 0.0 0.0"/>
      <inertia ixx="3.36483410344631E-03" ixy="-6.95997852501698E-05" ixz="-3.20907144882021E-06" iyy="1.55398903526845E-03" iyz="-6.72868939256485E-06" izz="4.10079899218125E-03"/>
    </inertial>
    <visual>
      <origin xyz="0.0 0.0 0.0" rpy="0 0 0"/>
      <geometry>
        <mesh filename="3obj/link_head_tilt.3obj.obj"/>
      </geometry>
    </visual>
    <collision>
      <origin xyz="0.0 0.0 0.0" rpy="0 0 0"/>
      <geometry>
        <mesh filename="coarse_meshes/link_head_tilt_vhacd.obj"/>
      </geometry>
    </collision>
  </link>





  <joint name="joint_torso" type="revolute">
    <parent link="link_base"/>
    <child link="link_torso"/>
    <axis xyz="0 0 1"/>
    <origin xyz="9.30157781734657E-16 -7.86343700838104E-17 0.5945" rpy="0 0 0"/>
    <limit lower="-4.49" upper="1.35" velocity="2.0" acceleration="2.0" jerk="51" effort="10.0"/>
  </joint>
  <joint name="joint_shoulder" type="revolute">
    <parent link="link_torso"/>
    <child link="link_shoulder"/>
    <axis xyz="0 1 0"/>
    <origin xyz="-8.70514704970795E-16 -0.16728852885 0.113" rpy="0 0 0"/>
    <limit lower="-2.66" upper="3.18" velocity="2.0" acceleration="2.0" jerk="51" effort="10.0"/>
  </joint>
  <joint name="joint_bicep" type="revolute">
    <parent link="link_shoulder"/>
    <child link="link_bicep"/>
    <axis xyz="0 0 1"/>
    <origin xyz="2.06492558283399E-16 2.28900000000007E-03 0.21502852885" rpy="0 0 0"/>
    <limit lower="-2.13" upper="3.71" velocity="2.0" acceleration="2.0" jerk="51" effort="10.0"/>
  </joint>
  <joint name="joint_elbow" type="revolute">
    <parent link="link_bicep"/>
    <child link="link_elbow"/>
    <axis xyz="0 1 0"/>
    <origin xyz="-2.21098558137003E-16 -0.064 0.1849715" rpy="0 0 0"/>
    <limit lower="-2.05" upper="3.79" velocity="2.5" acceleration="2.0" jerk="51" effort="10.0"/>
  </joint>
  <joint name="joint_forearm" type="revolute">
    <parent link="link_elbow"/>
    <child link="link_forearm"/>
    <axis xyz="0 0 1"/>
    <origin xyz="-2.91747336683945E-16 -0.101 9.15000000000024E-02" rpy="0 0 0"/>
    <limit lower="-2.92" upper="2.92" velocity="3.0" acceleration="2.0" jerk="51" effort="10.0"/>
  </joint>
  <joint name="joint_wrist" type="revolute">
    <parent link="link_forearm"/>
    <child link="link_wrist"/>
    <axis xyz="0 1 0"/>
    <origin xyz="3.44300437270003E-16 -6.04000000000005E-03 0.2735" rpy="0 0 0"/>
    <limit lower="-1.79" upper="1.79" velocity="3.0" acceleration="2.0" jerk="51" effort="10.0"/>
  </joint>
  <joint name="joint_gripper" type="revolute">
    <parent link="link_wrist"/>
    <child link="link_gripper"/>
    <axis xyz="0 0 1"/>
    <origin xyz="1.38181343846767E-16 6.03839999999994E-03 0.10911" rpy="0 0 0"/>
    <limit lower="-4.49" upper="1.35" velocity="3.0" acceleration="2.0" jerk="51" effort="10.0"/>
  </joint>

 
  <joint name="joint_head_pan" type="revolute">
    <parent link="link_base"/>
    <child link="link_head_pan"/>
    <axis xyz="0 0 1"/>
    <origin xyz="-8.21892185644845E-18 -2.87810584930212E-18 1.16902000000001" rpy="0 0 0"/>
    <limit lower="-3.79" upper="2.22" velocity="2.0" acceleration="8.0" jerk="1000" effort="10.0"/>
  </joint>
  <joint name="joint_head_tilt" type="revolute">
    <parent link="link_head_pan"/>
    <child link="link_head_tilt"/>
    <axis xyz="0 1 0"/>
    <origin xyz="7.18099999986988E-02 2.87810584930212E-18 0.11848" rpy="0 0 0"/>
    <limit lower="-1.17" upper="1.17" velocity="2.0" acceleration="8.0" jerk="100" effort="10.0"/>
  </joint>

</robot>
