<mujoco model="panda">
    <compiler angle="radian" />
    <default>
        <default class="panda">
            <joint armature="0.1" damping="1" axis="0 0 1" range="-2.8973 2.8973"/>
        </default>
    </default>
    <asset>
        <mesh name="link0" file="link0.stl" />
        <mesh name="link1" file="link1.stl" />
        <mesh name="link2" file="link2.stl" />
        <mesh name="link3" file="link3.stl" />
        <mesh name="link4" file="link4.stl" />
        <mesh name="link5" file="link5.stl" />
        <mesh name="link6" file="link6.stl" />
        <mesh name="link7" file="link7.stl" />
        <mesh name="flange" file="flange.STL" />
        <mesh name="camera_link" file="camera_link.STL" />
        <mesh name="basebody1_link" file="basebody1_link.STL" />
        <mesh name="cable1_link" file="cable1_link.STL" />
        <mesh name="cable2_link" file="cable2_link.STL" />
        <mesh name="basebody2_link" file="basebody2_link.STL" />
        <mesh name="finger_link1_1" file="finger_link1_1.STL" />
        <mesh name="finger_link1_2" file="finger_link1_2.STL" />
        <mesh name="finger_link1_3" file="finger_link1_3.STL" />
        <mesh name="finger_link1_4" file="finger_link1_4.STL" />
        <mesh name="finger_link2_1" file="finger_link2_1.STL" />
        <mesh name="finger_link2_2" file="finger_link2_2.STL" />
        <mesh name="finger_link2_3" file="finger_link2_3.STL" />
        <mesh name="finger_link2_4" file="finger_link2_4.STL" />
    </asset>
    <worldbody>
        <geom type="mesh" rgba="1 1 1 1" mesh="link0" />
        <body name="panda_link1" pos="0 0 0.333" childclass="panda">
            <inertial pos="0 -0.04 -0.05" mass="2.7" diaginertia="0.1 0.1 0.1" />
            <joint name="joint1" pos="0 0 0" axis="0 0 1" limited="true" range="-2.8973 2.8973" />
            <geom type="mesh" rgba="1 1 1 1" mesh="link1" />
            <body name="panda_link2" pos="0 0 0" quat="0.707107 -0.707107 0 0">
                <inertial pos="0 -0.04 0.06" mass="2.73" diaginertia="0.1 0.1 0.1" />
                <joint name="joint2" pos="0 0 0" axis="0 0 1" limited="true" range="-1.7628 1.7628" />
                <geom type="mesh" rgba="1 1 1 1" mesh="link2" />
                <body name="panda_link3" pos="0 -0.316 0" quat="0.707107 0.707107 0 0">
                    <inertial pos="0.01 0.01 -0.05" mass="2.04" diaginertia="0.1 0.1 0.1" />
                    <joint name="joint3" pos="0 0 0" axis="0 0 1" limited="true" range="-2.8973 2.8973" />
                    <geom type="mesh" rgba="1 1 1 1" mesh="link3" />
                    <body name="panda_link4" pos="0.0825 0 0" quat="0.707107 0.707107 0 0">
                        <inertial pos="-0.03 0.03 0.02" mass="2.08" diaginertia="0.1 0.1 0.1" />
                        <joint name="joint4" pos="0 0 0" axis="0 0 1" limited="true" range="-3.0718 -0.0698" />
                        <geom type="mesh" rgba="1 1 1 1" mesh="link4" />
                        <body name="panda_link5" pos="-0.0825 0.384 0" quat="0.707107 -0.707107 0 0">
                            <inertial pos="0 0.04 -0.12" mass="3" diaginertia="0.1 0.1 0.1" />
                            <joint name="joint5" pos="0 0 0" axis="0 0 1" limited="true" range="-2.8975 2.8975" />
                            <geom type="mesh" rgba="1 1 1 1" mesh="link5" />
                            <body name="panda_link6" pos="0 0 0" quat="0.707107 0.707107 0 0">
                                <inertial pos="0.04 0 0" mass="1.3" diaginertia="0.1 0.1 0.1" />
                                <joint name="joint6" pos="0 0 0" axis="0 0 1" limited="true" range="-0.0175 3.7525" />
                                <geom type="mesh" rgba="1 1 1 1" mesh="link6" />
                                <body name="panda_link7" pos="0.088 0 0" quat="0.707107 0.707107 0 0">
                                    <inertial pos="0.00603255 -0.00680105 0.117405" quat="0.643693 0.662884 -0.266082 -0.274672" mass="0.827348" diaginertia="0.102376 0.102153 0.101089" />
                                    <joint name="joint7" pos="0 0 0" axis="0 0 1" limited="true" range="-2.8973 2.8973" />
                                    <geom type="mesh" rgba="1 1 1 1" mesh="link7" />
                                    <geom pos="0 0 0.107" quat="1.0254e-08 -0.92388 0.382683 2.47553e-08" type="mesh" rgba="1 1 1 1" mesh="flange" />
                                    <geom pos="0.0424264 -0.0424264 0.11" quat="-0.270599 -0.65328 0.270598 -0.653283" type="mesh" rgba="1 1 1 1" mesh="camera_link" />
                                    <geom pos="0 0 0.107" quat="1.0254e-08 -0.92388 0.382683 2.47553e-08" type="mesh" rgba="1 1 1 1" mesh="basebody1_link" />
                                    <geom pos="0 0 0.107" quat="1.0254e-08 -0.92388 0.382683 2.47553e-08" type="mesh" rgba="1 1 1 1" mesh="cable1_link" />
                                    <geom pos="0 0 0.107" quat="1.0254e-08 -0.92388 0.382683 2.47553e-08" type="mesh" rgba="1 1 1 1" mesh="cable2_link" />
                                    <geom pos="0 0 0.107" quat="1.0254e-08 -0.92388 0.382683 2.47553e-08" type="mesh" rgba="1 1 1 1" mesh="basebody2_link" />
                                    <body name="panda_leftfinger" pos="5.01713e-09 -5.01713e-09 0.2394" quat="0.270598 -0.653281 -0.2706 -0.653281">
                                        <inertial pos="-0.0361013 1.19509e-12 -0.0142925" quat="0 0.659247 0 0.751926" mass="0.0369122" diaginertia="2.11974e-05 2.05817e-05 1.99059e-06" />
                                        <joint name="finger_joint1" pos="0 0 0" axis="0 0 -1" type="slide" limited="true" range="0 0.04" />
                                        <geom type="mesh" rgba="1 1 1 1" mesh="finger_link1_1" />
                                        <geom type="mesh" rgba="1 1 1 1" mesh="finger_link1_2" />
                                        <geom type="mesh" rgba="1 1 1 1" mesh="finger_link1_3" />
                                        <geom type="mesh" rgba="0.29804 0.29804 0.29804 1" mesh="finger_link1_4" />
                                    </body>
                                    <body name="panda_rightfinger" pos="5.01713e-09 -5.01713e-09 0.2394" quat="-0.653281 -0.2706 0.65328 -0.270598">
                                        <inertial pos="-0.0361013 1.19512e-12 -0.0142925" quat="0 0.659247 0 0.751926" mass="0.0369122" diaginertia="2.11974e-05 2.05817e-05 1.99059e-06" />
                                        <joint name="finger_joint2" pos="0 0 0" axis="0 0 -1" type="slide" limited="true" range="0 0.04" />
                                        <geom type="mesh" rgba="1 1 1 1" mesh="finger_link2_1" />
                                        <geom type="mesh" rgba="1 1 1 1" mesh="finger_link2_2" />
                                        <geom type="mesh" rgba="1 1 1 1" mesh="finger_link2_3" />
                                        <geom type="mesh" rgba="0.29804 0.29804 0.29804 1" mesh="finger_link2_4" />
                                    </body>
                                </body>
                            </body>
                        </body>
                    </body>
                </body>
            </body>
        </body>
    </worldbody>
    
    <equality>
        <joint joint1="finger_joint1" joint2="finger_joint2" solimp="0.95 0.99 0.001" solref="0.005 1"/>
    </equality>

    <actuator>
        <general name="actuator1" joint="joint1" biastype="affine" gainprm="10000 0 0" biasprm="0 -10000 -250" forcerange="-100 100"/>
        <general name="actuator2" joint="joint2" biastype="affine" gainprm="10000 0 0" biasprm="0 -10000 -250" ctrlrange="-1.7628 1.7628" forcerange="-100 100"/>
        <general name="actuator3" joint="joint3" biastype="affine" gainprm="10000 0 0" biasprm="0 -10000 -250" forcerange="-100 100"/>
        <general name="actuator4" joint="joint4" biastype="affine" gainprm="10000 0 0" biasprm="0 -10000 -250" ctrlrange="-3.0718 -0.0698" forcerange="-100 100"/>
        <general name="actuator5" joint="joint5" biastype="affine" gainprm="10000 0 0" biasprm="0 -10000 -250" forcerange="-100 100"/>
        <general name="actuator6" joint="joint6" biastype="affine" gainprm="10000 0 0" biasprm="0 -10000 -250" ctrlrange="-0.0175 3.7525" forcerange="-100 100"/>
        <general name="actuator7" joint="joint7" biastype="affine" gainprm="10000 0 0" biasprm="0 -10000 -250" forcerange="-100 100"/>
        <general name="finger_actuator1" joint="finger_joint1" biastype="affine" forcerange="-100 100" ctrlrange="0 0.04" gainprm="100" biasprm="0 -100 -10"/>
        <general name="finger_actuator2" joint="finger_joint2" biastype="affine" forcerange="-100 100" ctrlrange="0 0.04" gainprm="100" biasprm="0 -100 -10"/>
    </actuator>

    <contact>
        <exclude name="exclude_7_left" body1="panda_link7" body2="panda_leftfinger"/>
        <exclude name="exclude_7_right" body1="panda_link7" body2="panda_rightfinger"/>
        <exclude name="exclude_7_2" body1="panda_link7" body2="panda_link2"/>
        <exclude name="exclude_7_3" body1="panda_link7" body2="panda_link3"/>
        <exclude name="exclude_7_4" body1="panda_link7" body2="panda_link4"/>
        <exclude name="exclude_7_5" body1="panda_link7" body2="panda_link5"/>
        <exclude name="exclude_7_6" body1="panda_link7" body2="panda_link6"/>
    </contact>
</mujoco>
